Workbook

Sheet README
B1: IDP Site Needs and Gap Tracker
B2: Self-directed practice project on SYNTHETIC data — not an operational deployment and not real household data
B4: What it does | C4: Takes household assessments collected with a KoboToolbox form and turns them into a site-management picture: one current record per household, what each household still needs, which sites fall below service reference values, which households need a visit this week, and draft quantities for technical review.
B5: Why it was built | C5: Shaped by supporting displaced families in school shelters in Rafah, where households were asked for the same information repeatedly without seeing what happened next. The design keeps one current record per household, shows what is still missing, and turns open issues into a visit list.
B6: Data flow | C6: 1) Assessment form (IDP_Household_Needs_Assessment_XLSForm.xlsx, English and Arabic) → 2) Kobo_Import: paste the Kobo export here → 3) Import_Index: finds the latest consented assessment of each household → 4) Households: the current register → 5) Needs_Gaps: need, assistance received since that assessment, unmet need → 6) Follow_Up_List and Dashboard.
B7: Errors are prevented at collection | C7: The form enforces the rules before a submission is accepted: the four age groups must add up to the household size; pregnant or breastfeeding women cannot exceed women aged 12–49; winter-clothing gaps cannot exceed the number of children or adults; household codes must follow HH-000; shelter types are filtered by site. The tracker therefore does not clean data after the fact.
B8: History is kept | C8: A re-verification visit is a new submission, not an overwrite. Import_Index keeps every submission and marks the latest consented one per household (latest assessment date; if two fall on the same day, the one lower in the export). Assistance counts toward the current gap only if dated on or after that latest assessment, so items already counted as owned at re-verification are not subtracted twice.
B9: Data protection by design | C9: No names, ID numbers or phone numbers are collected. Households are identified by the code on their household card. Consent is asked first; if declined, the form ends and nothing is registered. Protection referrals carry no narrative detail.
B10: Priority flags | C10: The priority score only orders households for follow-up review by the responsible officer. It is not an eligibility or selection decision.
B11: Infant feeding | C11: Infant formula is never calculated as a distribution item. A reported infant-feeding difficulty triggers a referral to a nutrition / IYCF partner; the Referrals sheet records the partner’s outcome after assessment.
B12: Reference values | C12: People per tap, people per latrine and litres per person per day are indicative values from Sphere WASH indicators, used for practice; verify against the current Sphere Handbook and cluster guidance before any real use.
B13: Test it with your own Kobo account | C13: Upload the XLSForm to KoboToolbox, deploy it and submit a few test assessments. In Data → Downloads choose XLS, "XML values and headers", and untick "Include groups in headers". In a COPY of this workbook, paste the whole export (headers included) at cell A1 of Kobo_Import. Field_Map shows whether every field was found; the register rebuilds from your submissions in any column order. Logs that refer to synthetic codes will no longer match, which is expected in a test copy.
B14: Capacity | C14: Kobo_Import: 300 submissions and 104 columns. Register: 150 households.
B15: Colour legend | C15: Blue text = entered or imported data and assumptions. Black text on grey = formulas (do not overwrite). Grey headers = calculation columns. Status cells use colour and a text label, never colour alone.
B16: Scenario date | C16: Days-open and days-since-assessment calculations use the scenario date in Settings (synthetic winter scenario).

Sheet Dashboard
B1: IDP Site Needs and Gap Dashboard
B2: Synthetic practice data — scenario date: | D2: =Settings!$B$5 -> 46053 | F2: =IF(COUNTIF(Field_Map!$C$5:$C$31,"Found")=27,"Import check: all form fields found","Import check: "&(27-COUNTIF(Field_Map!$C$5:$C$31,"Found"))&" field(s) not found – see Field_Map") -> Import check: all form fields found
B3: Key figures
B4: Households registered (consented) | C4: =COUNTIF(Households!$A$5:$A$154,"?*") -> 120
B5: Individuals | C5: =SUM(Households!$H$5:$H$154) -> 798
B6: Assessments submitted (incl. re-verification) | C6: =COUNTIF(Import_Index!$C$5:$C$304,"yes") -> 146
B7: Re-verification visits | C7: =COUNTIFS(Import_Index!$C$5:$C$304,"yes",Import_Index!$E$5:$E$304,"reverification") -> 26
B8: Consent declined (nothing registered) | C8: =COUNTIF(Import_Index!$C$5:$C$304,"no") -> 2
B9: Households with an unmet need | C9: =COUNTIF(Needs_Gaps!$AH$5:$AH$154,"Yes") -> 119
B10: Share of households with an unmet need | C10: =IF(C4=0,0,C9/C4) -> 0.99166667
B11: ="Households with gaps in "&Settings!$B$33&"+ item types" -> Households with gaps in 4+ item types | C11: =COUNTIF(Needs_Gaps!$AI$5:$AI$154,">="&Settings!$B$33) -> 81
B12: High-priority households (for review) | C12: =COUNTIF(Households!$X$5:$X$154,"High") -> 23
B13: Households on this week’s follow-up list | C13: =COUNTIF(Households!$AF$5:$AF$154,">0") -> 37
B14: Households due for re-verification | C14: =COUNTIF(Households!$Y$5:$Y$154,"Yes") -> 17
B15: IYCF referrals still to be made | C15: =COUNTIF(Households!$AB$5:$AB$154,"Referral needed") -> 2
B16: Open referrals | C16: =COUNTIF(Referrals!$G$5:$G$52,"Referred")+COUNTIF(Referrals!$G$5:$G$52,"Acknowledged") -> 26
B17: Overdue referrals | C17: =COUNTIF(Referrals!$K$5:$K$52,"Overdue") -> 9
B18: Open maintenance issues | C18: =COUNTIF(Maintenance_Log!$H$5:$H$40,"Open")+COUNTIF(Maintenance_Log!$H$5:$H$40,"In progress") -> 20
B19: Open safety-related issues | C19: =COUNTIFS(Maintenance_Log!$H$5:$H$40,"<>Resolved",Maintenance_Log!$F$5:$F$40,"Yes") -> 7
B20: Draft quantities, estimated cost (USD, illustrative) | C20: =BoQ_Draft!$G$17 -> 29517
B23: Assessed need and coverage by item (assistance since latest assessment)
B24: Item | C24: Unit | D24: Total need | E24: Unmet | F24: Covered | G24: Share of need met
B25: Blankets | C25: pcs | D25: =SUM(Needs_Gaps!$D$5:$D$154) -> 896 | E25: =SUM(Needs_Gaps!$F$5:$F$154) -> 571 | F25: =D25-E25 -> 325 | G25: =IF(D25=0,0,F25/D25) -> 0.36272321
B26: Mattresses | C26: pcs | D26: =SUM(Needs_Gaps!$G$5:$G$154) -> 370 | E26: =SUM(Needs_Gaps!$I$5:$I$154) -> 265 | F26: =D26-E26 -> 105 | G26: =IF(D26=0,0,F26/D26) -> 0.28378378
B27: Tarpaulins | C27: sheets | D27: =SUM(Needs_Gaps!$J$5:$J$154) -> 28 | E27: =SUM(Needs_Gaps!$L$5:$L$154) -> 21 | F27: =D27-E27 -> 7 | G27: =IF(D27=0,0,F27/D27) -> 0.25
B28: Tent replacement | C28: tents | D28: =SUM(Needs_Gaps!$M$5:$M$154) -> 9 | E28: =SUM(Needs_Gaps!$O$5:$O$154) -> 9 | F28: =D28-E28 -> 0 | G28: =IF(D28=0,0,F28/D28) -> 0
B29: Shelter repair kits | C29: kits | D29: =SUM(Needs_Gaps!$P$5:$P$154) -> 27 | E29: =SUM(Needs_Gaps!$R$5:$R$154) -> 17 | F29: =D29-E29 -> 10 | G29: =IF(D29=0,0,F29/D29) -> 0.37037037
B30: Winter clothing – children | C30: sets | D30: =SUM(Needs_Gaps!$S$5:$S$154) -> 286 | E30: =SUM(Needs_Gaps!$U$5:$U$154) -> 198 | F30: =D30-E30 -> 88 | G30: =IF(D30=0,0,F30/D30) -> 0.30769231
B31: Winter clothing – adults | C31: sets | D31: =SUM(Needs_Gaps!$V$5:$V$154) -> 123 | E31: =SUM(Needs_Gaps!$X$5:$X$154) -> 101 | F31: =D31-E31 -> 22 | G31: =IF(D31=0,0,F31/D31) -> 0.17886179
B32: Diapers | C32: packs/month | D32: =SUM(Needs_Gaps!$Y$5:$Y$154) -> 260 | E32: =SUM(Needs_Gaps!$AA$5:$AA$154) -> 182 | F32: =D32-E32 -> 78 | G32: =IF(D32=0,0,F32/D32) -> 0.3
B33: Family hygiene kits | C33: kits/month | D33: =SUM(Needs_Gaps!$AB$5:$AB$154) -> 120 | E33: =SUM(Needs_Gaps!$AD$5:$AD$154) -> 43 | F33: =D33-E33 -> 77 | G33: =IF(D33=0,0,F33/D33) -> 0.64166667
B34: Menstrual hygiene kits | C34: kits/month | D34: =SUM(Needs_Gaps!$AE$5:$AE$154) -> 192 | E34: =SUM(Needs_Gaps!$AG$5:$AG$154) -> 161 | F34: =D34-E34 -> 31 | G34: =IF(D34=0,0,F34/D34) -> 0.16145833
B37: Households by site
B38: Site | C38: Households | D38: Individuals | E38: With multiple gaps | F38: Share with multiple gaps | G38: High priority
B39: Site A – School Shelter | C39: =COUNTIF(Households!$B$5:$B$154,B39) -> 34 | D39: =SUMIF(Households!$B$5:$B$154,B39,Households!$H$5:$H$154) -> 222 | E39: =COUNTIFS(Needs_Gaps!$B$5:$B$154,B39,Needs_Gaps!$AI$5:$AI$154,">="&Settings!$B$33) -> 23 | F39: =IF(C39=0,0,E39/C39) -> 0.67647059 | G39: =COUNTIFS(Households!$B$5:$B$154,B39,Households!$X$5:$X$154,"High") -> 6
B40: Site B – School Shelter | C40: =COUNTIF(Households!$B$5:$B$154,B40) -> 30 | D40: =SUMIF(Households!$B$5:$B$154,B40,Households!$H$5:$H$154) -> 202 | E40: =COUNTIFS(Needs_Gaps!$B$5:$B$154,B40,Needs_Gaps!$AI$5:$AI$154,">="&Settings!$B$33) -> 10 | F40: =IF(C40=0,0,E40/C40) -> 0.33333333 | G40: =COUNTIFS(Households!$B$5:$B$154,B40,Households!$X$5:$X$154,"High") -> 3
B41: Site C – Informal Tent Area | C41: =COUNTIF(Households!$B$5:$B$154,B41) -> 36 | D41: =SUMIF(Households!$B$5:$B$154,B41,Households!$H$5:$H$154) -> 258 | E41: =COUNTIFS(Needs_Gaps!$B$5:$B$154,B41,Needs_Gaps!$AI$5:$AI$154,">="&Settings!$B$33) -> 32 | F41: =IF(C41=0,0,E41/C41) -> 0.88888889 | G41: =COUNTIFS(Households!$B$5:$B$154,B41,Households!$X$5:$X$154,"High") -> 9
B42: Site D – Collective Centre | C42: =COUNTIF(Households!$B$5:$B$154,B42) -> 20 | D42: =SUMIF(Households!$B$5:$B$154,B42,Households!$H$5:$H$154) -> 116 | E42: =COUNTIFS(Needs_Gaps!$B$5:$B$154,B42,Needs_Gaps!$AI$5:$AI$154,">="&Settings!$B$33) -> 16 | F42: =IF(C42=0,0,E42/C42) -> 0.8 | G42: =COUNTIFS(Households!$B$5:$B$154,B42,Households!$X$5:$X$154,"High") -> 5
B45: Follow-up reasons this week (households; one household can have several)
B46: Reason | C46: Households
...

Sheet Follow_Up_List
A1: Weekly follow-up visit list | F1: Households to visit: | G1: =COUNTIF(Households!$AF$5:$AF$154,">0") -> 37 | I1: Week of: | J1: =Settings!$B$5 -> 46053
A2: Households with at least one open issue, ordered by number of reasons, then priority score, then code. A visit that updates the household is recorded as a re-verification submission in Kobo.
A4: # | B4: HH code | C4: Site | D4: Shelter | E4: Priority band | F4: Reasons | G4: Overdue referrals | H4: IYCF referral | I4: Tent replacement pending | J4: Shelter repair open | K4: Re-verification due | L4: Suggested actions for the visit | M4: Sort key | N4: Register row
A5: =IF(ROW()-4<=$G$1,ROW()-4,"") -> 1 | B5: =IF($A5="","",INDEX(Households!$A$5:$A$154,$N5)) -> HH-098 | C5: =IF($A5="","",INDEX(Households!$B$5:$B$154,$N5)) -> Site C – Informal Tent Area | D5: =IF($A5="","",INDEX(Households!$C$5:$C$154,$N5)&" – "&INDEX(Households!$D$5:$D$154,$N5)) -> Tent – Adequate | E5: =IF($A5="","",INDEX(Households!$X$5:$X$154,$N5)) -> High | F5: =IF($A5="","",INDEX(Households!$AE$5:$AE$154,$N5)) -> 2 | G5: =IF($A5="","",IF(INDEX(Households!$AA$5:$AA$154,$N5)>0,INDEX(Households!$AA$5:$AA$154,$N5),"")) -> 1 | H5: =IF($A5="","",IF(INDEX(Households!$AB$5:$AB$154,$N5)="Referral needed","Referral needed","")) | I5: =IF($A5="","",INDEX(Households!$AC$5:$AC$154,$N5)) | J5: =IF($A5="","",INDEX(Households!$AD$5:$AD$154,$N5)) | K5: =IF($A5="","",INDEX(Households!$Y$5:$Y$154,$N5)) -> Yes | L5: =IF($A5="","",SUBSTITUTE(IF(N(G5)>0,"Chase overdue referral with the service provider; ","")&IF(H5="Referral needed","Make the IYCF referral to the nutrition partner; ","")&IF(I5="Yes","Confirm tent replacement with the shelter partner; ","")&IF(J5="Yes","Check the household shelter repair; ","")&IF(K5="Yes","Re-verify the household (new Kobo submission); ","")&"|","; |","")) -> Chase overdue referral with the service provider; Re-verify the household (new Kobo submission) | M5: =IF($A5="","",LARGE(Households!$AF$5:$AF$154,$A5)) -> 205902 | N5: =IF($A5="","",MATCH($M5,Households!$AF$5:$AF$154,0)) -> 98
A6: =IF(ROW()-4<=$G$1,ROW()-4,"") -> 2 | B6: =IF($A6="","",INDEX(Households!$A$5:$A$154,$N6)) -> HH-099 | C6: =IF($A6="","",INDEX(Households!$B$5:$B$154,$N6)) -> Site C – Informal Tent Area | D6: =IF($A6="","",INDEX(Households!$C$5:$C$154,$N6)&" – "&INDEX(Households!$D$5:$D$154,$N6)) -> Tent – Unusable | E6: =IF($A6="","",INDEX(Households!$X$5:$X$154,$N6)) -> Medium | F6: =IF($A6="","",INDEX(Households!$AE$5:$AE$154,$N6)) -> 2 | G6: =IF($A6="","",IF(INDEX(Households!$AA$5:$AA$154,$N6)>0,INDEX(Households!$AA$5:$AA$154,$N6),"")) -> 1 | H6: =IF($A6="","",IF(INDEX(Households!$AB$5:$AB$154,$N6)="Referral needed","Referral needed","")) | I6: =IF($A6="","",INDEX(Households!$AC$5:$AC$154,$N6)) -> Yes | J6: =IF($A6="","",INDEX(Households!$AD$5:$AD$154,$N6)) | K6: =IF($A6="","",INDEX(Households!$Y$5:$Y$154,$N6)) | L6: =IF($A6="","",SUBSTITUTE(IF(N(G6)>0,"Chase overdue referral with the service provider; ","")&IF(H6="Referral needed","Make the IYCF referral to the nutrition partner; ","")&IF(I6="Yes","Confirm tent replacement with the shelter partner; ","")&IF(J6="Yes","Check the household shelter repair; ","")&IF(K6="Yes","Re-verify the household (new Kobo submission); ","")&"|","; |","")) -> Chase overdue referral with the service provider; Confirm tent replacement with the shelter partner | M6: =IF($A6="","",LARGE(Households!$AF$5:$AF$154,$A6)) -> 203901 | N6: =IF($A6="","",MATCH($M6,Households!$AF$5:$AF$154,0)) -> 99
A7: =IF(ROW()-4<=$G$1,ROW()-4,"") -> 3 | B7: =IF($A7="","",INDEX(Households!$A$5:$A$154,$N7)) -> HH-072 | C7: =IF($A7="","",INDEX(Households!$B$5:$B$154,$N7)) -> Site C – Informal Tent Area | D7: =IF($A7="","",INDEX(Households!$C$5:$C$154,$N7)&" – "&INDEX(Households!$D$5:$D$154,$N7)) -> Tent – Unusable | E7: =IF($A7="","",INDEX(Households!$X$5:$X$154,$N7)) -> High | F7: =IF($A7="","",INDEX(Households!$AE$5:$AE$154,$N7)) -> 1 | G7: =IF($A7="","",IF(INDEX(Households!$AA$5:$AA$154,$N7)>0,INDEX(Households!$AA$5:$AA$154,$N7),"")) | H7: =IF($A7="","",IF(INDEX(Households!$AB$5:$AB$154,$N7)="Referral needed","Referral needed","")) | I7: =IF($A7="","",INDEX(Households!$AC$5:$AC$154,$N7)) -> Yes | J7: =IF($A7="","",INDEX(Households!$AD$5:$AD$154,$N7)) | K7: =IF($A7="","",INDEX(Households!$Y$5:$Y$154,$N7)) | L7: =IF($A7="","",SUBSTITUTE(IF(N(G7)>0,"Chase overdue referral with the service provider; ","")&IF(H7="Referral needed","Make the IYCF referral to the nutrition partner; ","")&IF(I7="Yes","Confirm tent replacement with the shelter partner; ","")&IF(J7="Yes","Check the household shelter repair; ","")&IF(K7="Yes","Re-verify the household (new Kobo submission); ","")&"|","; |","")) -> Confirm tent replacement with the shelter partner | M7: =IF($A7="","",LARGE(Households!$AF$5:$AF$154,$A7)) -> 108928 | N7: =IF($A7="","",MATCH($M7,Households!$AF$5:$AF$154,0)) -> 72
A8: =IF(ROW()-4<=$G$1,ROW()-4,"") -> 4 | B8: =IF($A8="","",INDEX(Households!$A$5:$A$154,$N8)) -> HH-095 | C8: =IF($A8="","",INDEX(Households!$B$5:$B$154,$N8)) -> Site C – Informal Tent Area | D8: =IF($A8="","",INDEX(Households!$C$5:$C$154,$N8)&" – "&INDEX(Households!$D$5:$D$154,$N8)) -> Tent – Unusable | E8: =IF($A8="","",INDEX(Households!$X$5:$X$154,$N8)) -> High | F8: =IF($A8="","",INDEX(Households!$AE$5:$AE$154,$N8)) -> 1 | G8: =IF($A8="","",IF(INDEX(Households!$AA$5:$AA$154,$N8)>0,INDEX(Households!$AA$5:$AA$154,$N8),"")) | H8: =IF($A8="","",IF(INDEX(Households!$AB$5:$AB$154,$N8)="Referral needed","Referral needed","")) | I8: =IF($A8="","",INDEX(Households!$AC$5:$AC$154,$N8)) -> Yes | J8: =IF($A8="","",INDEX(Households!$AD$5:$AD$154,$N8)) | K8: =IF($A8="","",INDEX(Households!$Y$5:$Y$154,$N8)) | L8: =IF($A8="","",SUBSTITUTE(IF(N(G8)>0,"Chase overdue referral with the service provider; ","")&IF(H8="Referral needed","Make the IYCF referral to the nutrition partner; ","")&IF(I8="Yes","Confirm tent replacement with the shelter partner; ","")&IF(J8="Yes","Check the household shelter repair; ","")&IF(K8="Yes","Re-verify the household (new Kobo submission); ","")&"|","; |","")) -> Confirm tent replacement with the shelter partner | M8: =IF($A8="","",LARGE(Households!$AF$5:$AF$154,$A8)) -> 108905 | N8: =IF($A8="","",MATCH($M8,Households!$AF$5:$AF$154,0)) -> 95
A9: =IF(ROW()-4<=$G$1,ROW()-4,"") -> 5 | B9: =IF($A9="","",INDEX(Households!$A$5:$A$154,$N9)) -> HH-029 | C9: =IF($A9="","",INDEX(Households!$B$5:$B$154,$N9)) -> Site A – School Shelter | D9: =IF($A9="","",INDEX(Households!$C$5:$C$154,$N9)&" – "&INDEX(Households!$D$5:$D$154,$N9)) -> Classroom – Damaged | E9: =IF($A9="","",INDEX(Households!$X$5:$X$154,$N9)) -> High | F9: =IF($A9="","",INDEX(Households!$AE$5:$AE$154,$N9)) -> 1 | G9: =IF($A9="","",IF(INDEX(Households!$AA$5:$AA$154,$N9)>0,INDEX(Households!$AA$5:$AA$154,$N9),"")) | H9: =IF($A9="","",IF(INDEX(Households!$AB$5:$AB$154,$N9)="Referral needed","Referral needed","")) | I9: =IF($A9="","",INDEX(Households!$AC$5:$AC$154,$N9)) | J9: =IF($A9="","",INDEX(Households!$AD$5:$AD$154,$N9)) | K9: =IF($A9="","",INDEX(Households!$Y$5:$Y$154,$N9)) -> Yes | L9: =IF($A9="","",SUBSTITUTE(IF(N(G9)>0,"Chase overdue referral with the service provider; ","")&IF(H9="Referral needed","Make the IYCF referral to the nutrition partner; ","")&IF(I9="Yes","Confirm tent replacement with the shelter partner; ","")&IF(J9="Yes","Check the household shelter repair; ","")&IF(K9="Yes","Re-verify the household (new Kobo submission); ","")&"|","; |","")) -> Re-verify the household (new Kobo submission) | M9: =IF($A9="","",LARGE(Households!$AF$5:$AF$154,$A9)) -> 107971 | N9: =IF($A9="","",MATCH($M9,Households!$AF$5:$AF$154,0)) -> 29
A10: =IF(ROW()-4<=$G$1,ROW()-4,"") -> 6 | B10: =IF($A10="","",INDEX(Households!$A$5:$A$154,$N10)) -> HH-070 | C10: =IF($A10="","",INDEX(Households!$B$5:$B$154,$N10)) -> Site C – Informal Tent Area | D10: =IF($A10="","",INDEX(Households!$C$5:$C$154,$N10)&" – "&INDEX(Households!$D$5:$D$154,$N10)) -> Makeshift shelter – Unusable | E10: =IF($A10="","",INDEX(Households!$X$5:$X$154,$N10)) -> High | F10: =IF($A10="","",INDEX(Households!$AE$5:$AE$154,$N10)) -> 1 | G10: =IF($A10="","",IF(INDEX(Households!$AA$5:$AA$154,$N10)>0,INDEX(Households!$AA$5:$AA$154,$N10),"")) | H10: =IF($A10="","",IF(INDEX(Households!$AB$5:$AB$154,$N10)="Referral needed","Referral needed","")) | I10: =IF($A10="","",INDEX(Households!$AC$5:$AC$154,$N10)) -> Yes | J10: =IF($A10="","",INDEX(Households!$AD$5:$AD$154,$N10)) | K10: =IF($A10="","",INDEX(Households!$Y$5:$Y$154,$N10)) | L10: =IF($A10="","",SUBSTITUTE(IF(N(G10)>0,"Chase overdue referral with the service provider; ","")&IF(H10="Referral needed","Make the IYCF referral to the nutrition partner; ","")&IF(I10="Yes","Confirm tent replacement with the shelter partner; ","")&IF(J10="Yes","Check the household shelter repair; ","")&IF(K10="Yes","Re-verify the household (new Kobo submission); ","")&"|","; |","")) -> Confirm tent replacement with the shelter partner | M10: =IF($A10="","",LARGE(Households!$AF$5:$AF$154,$A10)) -> 107930 | N10: =IF($A10="","",MATCH($M10,Households!$AF$5:$AF$154,0)) -> 70
A11: =IF(ROW()-4<=$G$1,ROW()-4,"") -> 7 | B11: =IF($A11="","",INDEX(Households!$A$5:$A$154,$N11)) -> HH-014 | C11: =IF($A11="","",INDEX(Households!$B$5:$B$154,$N11)) -> Site A – School Shelter | D11: =IF($A11="","",INDEX(Households!$C$5:$C$154,$N11)&" – "&INDEX(Households!$D$5:$D$154,$N11)) -> Classroom – Adequate | E11: =IF($A11="","",INDEX(Households!$X$5:$X$154,$N11)) -> High | F11: =IF($A11="","",INDEX(Households!$AE$5:$AE$154,$N11)) -> 1 | G11: =IF($A11="","",IF(INDEX(Households!$AA$5:$AA$154,$N11)>0,INDEX(Households!$AA$5:$AA$154,$N11),"")) -> 1 | H11: =IF($A11="","",IF(INDEX(Households!$AB$5:$AB$154,$N11)="Referral needed","Referral needed","")) | I11: =IF($A11="","",INDEX(Households!$AC$5:$AC$154,$N11)) | J11: =IF($A11="","",INDEX(Households!$AD$5:$AD$154,$N11)) | K11: =IF($A11="","",INDEX(Households!$Y$5:$Y$154,$N11)) | L11: =IF($A11="","",SUBSTITUTE(IF(N(G11)>0,"Chase overdue referral with the service provider; ","")&IF(H11="Referral needed","Make the IYCF referral to the nutrition partner; ","")&IF(I11="Yes","Confirm tent replacement with the shelter partner; ","")&IF(J11="Yes","Check the household shelter repair; ","")&IF(K11="Yes","Re-verify the household (new Kobo submission); ","")&"|","; |","")) -> Chase overdue referral with the service provider | M11: =IF($A11="","",LARGE(Households!$AF$5:$AF$154,$A11)) -> 106986 | N11: =IF($A11="","",MATCH($M11,Households!$AF$5:$AF$154,0)) -> 14
A12: =IF(ROW()-4<=$G$1,ROW()-4,"") -> 8 | B12: =IF($A12="","",INDEX(Households!$A$5:$A$154,$N12)) -> HH-058 | C12: =IF($A12="","",INDEX(Households!$B$5:$B$154,$N12)) -> Site B – School Shelter | D12: =IF($A12="","",INDEX(Households!$C$5:$C$154,$N12)&" – "&INDEX(Households!$D$5:$D$154,$N12)) -> Classroom – Adequate | E12: =IF($A12="","",INDEX(Households!$X$5:$X$154,$N12)) -> High | F12: =IF($A12="","",INDEX(Households!$AE$5:$AE$154,$N12)) -> 1 | G12: =IF($A12="","",IF(INDEX(Households!$AA$5:$AA$154,$N12)>0,INDEX(Households!$AA$5:$AA$154,$N12),"")) | H12: =IF($A12="","",IF(INDEX(Households!$AB$5:$AB$154,$N12)="Referral needed","Referral needed","")) | I12: =IF($A12="","",INDEX(Households!$AC$5:$AC$154,$N12)) | J12: =IF($A12="","",INDEX(Households!$AD$5:$AD$154,$N12)) | K12: =IF($A12="","",INDEX(Households!$Y$5:$Y$154,$N12)) -> Yes | L12: =IF($A12="","",SUBSTITUTE(IF(N(G12)>0,"Chase overdue referral with the service provider; ","")&IF(H12="Referral needed","Make the IYCF referral to the nutrition partner; ","")&IF(I12="Yes","Confirm tent replacement with the shelter partner; ","")&IF(J12="Yes","Check the household shelter repair; ","")&IF(K12="Yes","Re-verify the household (new Kobo submission); ","")&"|","; |","")) -> Re-verify the household (new Kobo submission) | M12: =IF($A12="","",LARGE(Households!$AF$5:$AF$154,$A12)) -> 106942 | N12: =IF($A12="","",MATCH($M12,Households!$AF$5:$AF$154,0)) -> 58
A13: =IF(ROW()-4<=$G$1,ROW()-4,"") -> 9 | B13: =IF($A13="","",INDEX(Households!$A$5:$A$154,$N13)) -> HH-071 | C13: =IF($A13="","",INDEX(Households!$B$5:$B$154,$N13)) -> Site C – Informal Tent Area | D13: =IF($A13="","",INDEX(Households!$C$5:$C$154,$N13)&" – "&INDEX(Households!$D$5:$D$154,$N13)) -> Makeshift shelter – Damaged | E13: =IF($A13="","",INDEX(Households!$X$5:$X$154,$N13)) -> High | F13: =IF($A13="","",INDEX(Households!$AE$5:$AE$154,$N13)) -> 1 | G13: =IF($A13="","",IF(INDEX(Households!$AA$5:$AA$154,$N13)>0,INDEX(Households!$AA$5:$AA$154,$N13),"")) | H13: =IF($A13="","",IF(INDEX(Households!$AB$5:$AB$154,$N13)="Referral needed","Referral needed","")) | I13: =IF($A13="","",INDEX(Households!$AC$5:$AC$154,$N13)) | J13: =IF($A13="","",INDEX(Households!$AD$5:$AD$154,$N13)) -> Yes | K13: =IF($A13="","",INDEX(Households!$Y$5:$Y$154,$N13)) | L13: =IF($A13="","",SUBSTITUTE(IF(N(G13)>0,"Chase overdue referral with the service provider; ","")&IF(H13="Referral needed","Make the IYCF referral to the nutrition partner; ","")&IF(I13="Yes","Confirm tent replacement with the shelter partner; ","")&IF(J13="Yes","Check the household shelter repair; ","")&IF(K13="Yes","Re-verify the household (new Kobo submission); ","")&"|","; |","")) -> Check the household shelter repair | M13: =IF($A13="","",LARGE(Households!$AF$5:$AF$154,$A13)) -> 106929 | N13: =IF($A13="","",MATCH($M13,Households!$AF$5:$AF$154,0)) -> 71
A14: =IF(ROW()-4<=$G$1,ROW()-4,"") -> 10 | B14: =IF($A14="","",INDEX(Households!$A$5:$A$154,$N14)) -> HH-102 | C14: =IF($A14="","",INDEX(Households!$B$5:$B$154,$N14)) -> Site D – Collective Centre | D14: =IF($A14="","",INDEX(Households!$C$5:$C$154,$N14)&" – "&INDEX(Households!$D$5:$D$154,$N14)) -> Collective room – Damaged | E14: =IF($A14="","",INDEX(Households!$X$5:$X$154,$N14)) -> High | F14: =IF($A14="","",INDEX(Households!$AE$5:$AE$154,$N14)) -> 1 | G14: =IF($A14="","",IF(INDEX(Households!$AA$5:$AA$154,$N14)>0,INDEX(Households!$AA$5:$AA$154,$N14),"")) -> 1 | H14: =IF($A14="","",IF(INDEX(Households!$AB$5:$AB$154,$N14)="Referral needed","Referral needed","")) | I14: =IF($A14="","",INDEX(Households!$AC$5:$AC$154,$N14)) | J14: =IF($A14="","",INDEX(Households!$AD$5:$AD$154,$N14)) | K14: =IF($A14="","",INDEX(Households!$Y$5:$Y$154,$N14)) | L14: =IF($A14="","",SUBSTITUTE(IF(N(G14)>0,"Chase overdue referral with the service provider; ","")&IF(H14="Referral needed","Make the IYCF referral to the nutrition partner; ","")&IF(I14="Yes","Confirm tent replacement with the shelter partner; ","")&IF(J14="Yes","Check the household shelter repair; ","")&IF(K14="Yes","Re-verify the household (new Kobo submission); ","")&"|","; |","")) -> Chase overdue referral with the service provider | M14: =IF($A14="","",LARGE(Households!$AF$5:$AF$154,$A14)) -> 106898 | N14: =IF($A14="","",MATCH($M14,Households!$AF$5:$AF$154,0)) -> 102
A15: =IF(ROW()-4<=$G$1,ROW()-4,"") -> 11 | B15: =IF($A15="","",INDEX(Households!$A$5:$A$154,$N15)) -> HH-107 | C15: =IF($A15="","",INDEX(Households!$B$5:$B$154,$N15)) -> Site D – Collective Centre | D15: =IF($A15="","",INDEX(Households!$C$5:$C$154,$N15)&" – "&INDEX(Households!$D$5:$D$154,$N15)) -> Collective room – Adequate | E15: =IF($A15="","",INDEX(Households!$X$5:$X$154,$N15)) -> High | F15: =IF($A15="","",INDEX(Households!$AE$5:$AE$154,$N15)) -> 1 | G15: =IF($A15="","",IF(INDEX(Households!$AA$5:$AA$154,$N15)>0,INDEX(Households!$AA$5:$AA$154,$N15),"")) -> 1 | H15: =IF($A15="","",IF(INDEX(Households!$AB$5:$AB$154,$N15)="Referral needed","Referral needed","")) | I15: =IF($A15="","",INDEX(Households!$AC$5:$AC$154,$N15)) | J15: =IF($A15="","",INDEX(Households!$AD$5:$AD$154,$N15)) | K15: =IF($A15="","",INDEX(Households!$Y$5:$Y$154,$N15)) | L15: =IF($A15="","",SUBSTITUTE(IF(N(G15)>0,"Chase overdue referral with the service provider; ","")&IF(H15="Referral needed","Make the IYCF referral to the nutrition partner; ","")&IF(I15="Yes","Confirm tent replacement with the shelter partner; ","")&IF(J15="Yes","Check the household shelter repair; ","")&IF(K15="Yes","Re-verify the household (new Kobo submission); ","")&"|","; |","")) -> Chase overdue referral with the service provider | M15: =IF($A15="","",LARGE(Households!$AF$5:$AF$154,$A15)) -> 106893 | N15: =IF($A15="","",MATCH($M15,Households!$AF$5:$AF$154,0)) -> 107
A16: =IF(ROW()-4<=$G$1,ROW()-4,"") -> 12 | B16: =IF($A16="","",INDEX(Households!$A$5:$A$154,$N16)) -> HH-020 | C16: =IF($A16="","",INDEX(Households!$B$5:$B$154,$N16)) -> Site A – School Shelter | D16: =IF($A16="","",INDEX(Households!$C$5:$C$154,$N16)&" – "&INDEX(Households!$D$5:$D$154,$N16)) -> Classroom – Adequate | E16: =IF($A16="","",INDEX(Households!$X$5:$X$154,$N16)) -> High | F16: =IF($A16="","",INDEX(Households!$AE$5:$AE$154,$N16)) -> 1 | G16: =IF($A16="","",IF(INDEX(Households!$AA$5:$AA$154,$N16)>0,INDEX(Households!$AA$5:$AA$154,$N16),"")) | H16: =IF($A16="","",IF(INDEX(Households!$AB$5:$AB$154,$N16)="Referral needed","Referral needed","")) | I16: =IF($A16="","",INDEX(Households!$AC$5:$AC$154,$N16)) | J16: =IF($A16="","",INDEX(Households!$AD$5:$AD$154,$N16)) | K16: =IF($A16="","",INDEX(Households!$Y$5:$Y$154,$N16)) -> Yes | L16: =IF($A16="","",SUBSTITUTE(IF(N(G16)>0,"Chase overdue referral with the service provider; ","")&IF(H16="Referral needed","Make the IYCF referral to the nutrition partner; ","")&IF(I16="Yes","Confirm tent replacement with the shelter partner; ","")&IF(J16="Yes","Check the household shelter repair; ","")&IF(K16="Yes","Re-verify the household (new Kobo submission); ","")&"|","; |","")) -> Re-verify the household (new Kobo submission) | M16: =IF($A16="","",LARGE(Households!$AF$5:$AF$154,$A16)) -> 105980 | N16: =IF($A16="","",MATCH($M16,Households!$AF$5:$AF$154,0)) -> 20
... A154: =IF(ROW()-4<=$G$1,ROW()-4,"") | B154: =IF($A154="","",INDEX(Households!$A$5:$A$154,$N154)) | C154: =IF($A154="","",INDEX(Households!$B$5:$B$154,$N154)) | D154: =IF($A154="","",INDEX(Households!$C$5:$C$154,$N154)&" – "&INDEX(Households!$D$5:$D$154,$N154)) | E154: =IF($A154="","",INDEX(Households!$X$5:$X$154,$N154)) | F154: =IF($A154="","",INDEX(Households!$AE$5:$AE$154,$N154)) | G154: =IF($A154="","",IF(INDEX(Households!$AA$5:$AA$154,$N154)>0,INDEX(Households!$AA$5:$AA$154,$N154),"")) | H154: =IF($A154="","",IF(INDEX(Households!$AB$5:$AB$154,$N154)="Referral needed","Referral needed","")) | I154: =IF($A154="","",INDEX(Households!$AC$5:$AC$154,$N154)) | J154: =IF($A154="","",INDEX(Households!$AD$5:$AD$154,$N154)) | K154: =IF($A154="","",INDEX(Households!$Y$5:$Y$154,$N154)) | L154: =IF($A154="","",SUBSTITUTE(IF(N(G154)>0,"Chase overdue referral with the service provider; ","")&IF(H154="Referral needed","Make the IYCF referral to the nutrition partner; ","")&IF(I154="Yes","Confirm tent replacement with the shelter partner; ","")&IF(J154="Yes","Check the household shelter repair; ","")&IF(K154="Yes","Re-verify the household (new Kobo submission); ","")&"|","; |","")) | M154: =IF($A154="","",LARGE(Households!$AF$5:$AF$154,$A154)) | N154: =IF($A154="","",MATCH($M154,Households!$AF$5:$AF$154,0))

Sheet Households
A1: Household register — latest consented assessment per household
A2: Every cell is a formula reading Kobo_Import through Import_Index. Do not type here: a correction is a new submission (re-verification) in Kobo.
A4: HH code | B4: Site | C4: Shelter type | D4: Shelter condition | E4: Registration date | F4: Latest assessment | G4: Assessments | H4: Household size | I4: Female-headed | J4: Children under 2 | K4: Children 2–17 | L4: Adults 18–59 | M4: Older persons 60+ | N4: Women & girls 12–49 | O4: Pregnant / breast-feeding | P4: Persons with difficulties (WG domains) | Q4: Blankets owned | R4: Mattresses owned | S4: Children without winter clothes | T4: Adults without winter clothes | U4: Infant feeding difficulty | V4: Days since latest assessment | W4: Priority score | X4: Priority band (review) | Y4: Re-verification due | Z4: Open referrals | AA4: Overdue referrals | AB4: IYCF referral | AC4: Tent replacement pending | AD4: Shelter repair open | AE4: Follow-up reasons | AF4: Follow-up sort key | AG4: Source row in Kobo_Import
A5: =IF($AG5="","",IFERROR(INDEX(Kobo_Import!$A$2:$CZ$301,$AG5,Field_Map!$B$13)&"","")) -> HH-001 | B5: =IF($AG5="","",IF(IFERROR(INDEX(Kobo_Import!$A$2:$CZ$301,$AG5,Field_Map!$B$9)&"","")="","",IFERROR(INDEX(Lists!$N$5:$N$19,MATCH(INDEX(Kobo_Import!$A$2:$CZ$301,$AG5,Field_Map!$B$9)&"",Lists!$M$5:$M$19,0)),INDEX(Kobo_Import!$A$2:$CZ$301,$AG5,Field_Map!$B$9)&""))) -> Site A – School Shelter | C5: =IF($AG5="","",IF(IFERROR(INDEX(Kobo_Import!$A$2:$CZ$301,$AG5,Field_Map!$B$14)&"","")="","",IFERROR(INDEX(Lists!$N$5:$N$19,MATCH(INDEX(Kobo_Import!$A$2:$CZ$301,$AG5,Field_Map!$B$14)&"",Lists!$M$5:$M$19,0)),INDEX(Kobo_Import!$A$2:$CZ$301,$AG5,Field_Map!$B$14)&""))) -> Classroom | D5: =IF($AG5="","",IF(IFERROR(INDEX(Kobo_Import!$A$2:$CZ$301,$AG5,Field_Map!$B$15)&"","")="","",IFERROR(INDEX(Lists!$N$5:$N$19,MATCH(INDEX(Kobo_Import!$A$2:$CZ$301,$AG5,Field_Map!$B$15)&"",Lists!$M$5:$M$19,0)),INDEX(Kobo_Import!$A$2:$CZ$301,$AG5,Field_Map!$B$15)&""))) -> Adequate | E5: =IF($A5="","",IFERROR(INDEX(Import_Index!$D$5:$D$304,MATCH($A5&"|registration",Import_Index!$I$5:$I$304,0)),F5)) -> 46022 | F5: =IF($AG5="","",INDEX(Import_Index!$D$5:$D$304,$AG5)) -> 46022 | G5: =IF($A5="","",COUNTIFS(Import_Index!$B$5:$B$304,$A5,Import_Index!$C$5:$C$304,"yes")) -> 1 | H5: =IF($AG5="","",IFERROR(VALUE(INDEX(Kobo_Import!$A$2:$CZ$301,$AG5,Field_Map!$B$16)&""),0)) -> 8 | I5: =IF($AG5="","",IF(IFERROR(INDEX(Kobo_Import!$A$2:$CZ$301,$AG5,Field_Map!$B$17)&"","")="","",IFERROR(INDEX(Lists!$N$5:$N$19,MATCH(INDEX(Kobo_Import!$A$2:$CZ$301,$AG5,Field_Map!$B$17)&"",Lists!$M$5:$M$19,0)),INDEX(Kobo_Import!$A$2:$CZ$301,$AG5,Field_Map!$B$17)&""))) -> No | J5: =IF($AG5="","",IFERROR(VALUE(INDEX(Kobo_Import!$A$2:$CZ$301,$AG5,Field_Map!$B$18)&""),0)) -> 1 | K5: =IF($AG5="","",IFERROR(VALUE(INDEX(Kobo_Import!$A$2:$CZ$301,$AG5,Field_Map!$B$19)&""),0)) -> 5 | L5: =IF($AG5="","",IFERROR(VALUE(INDEX(Kobo_Import!$A$2:$CZ$301,$AG5,Field_Map!$B$20)&""),0)) -> 2 | M5: =IF($AG5="","",IFERROR(VALUE(INDEX(Kobo_Import!$A$2:$CZ$301,$AG5,Field_Map!$B$21)&""),0)) -> 0 | N5: =IF($AG5="","",IFERROR(VALUE(INDEX(Kobo_Import!$A$2:$CZ$301,$AG5,Field_Map!$B$22)&""),0)) -> 1 | O5: =IF($AG5="","",IFERROR(VALUE(INDEX(Kobo_Import!$A$2:$CZ$301,$AG5,Field_Map!$B$23)&""),0)) -> 1 | P5: =IF($AG5="","",IFERROR(VALUE(INDEX(Kobo_Import!$A$2:$CZ$301,$AG5,Field_Map!$B$24)&""),0)) -> 0 | Q5: =IF($AG5="","",IFERROR(VALUE(INDEX(Kobo_Import!$A$2:$CZ$301,$AG5,Field_Map!$B$25)&""),0)) -> 3 | R5: =IF($AG5="","",IFERROR(VALUE(INDEX(Kobo_Import!$A$2:$CZ$301,$AG5,Field_Map!$B$26)&""),0)) -> 1 | S5: =IF($AG5="","",IFERROR(VALUE(INDEX(Kobo_Import!$A$2:$CZ$301,$AG5,Field_Map!$B$27)&""),0)) -> 2 | T5: =IF($AG5="","",IFERROR(VALUE(INDEX(Kobo_Import!$A$2:$CZ$301,$AG5,Field_Map!$B$28)&""),0)) -> 1 | U5: =IF($AG5="","",IF(IFERROR(INDEX(Kobo_Import!$A$2:$CZ$301,$AG5,Field_Map!$B$29)&"","")="","",IFERROR(INDEX(Lists!$N$5:$N$19,MATCH(INDEX(Kobo_Import!$A$2:$CZ$301,$AG5,Field_Map!$B$29)&"",Lists!$M$5:$M$19,0)),INDEX(Kobo_Import!$A$2:$CZ$301,$AG5,Field_Map!$B$29)&""))) -> Yes | V5: =IF($A5="","",Settings!$B$5-F5) -> 31 | W5: =IF($A5="","",(J5>0)*Settings!$B$22+(P5>0)*Settings!$B$23+(M5>0)*Settings!$B$24+(O5>0)*Settings!$B$25+(I5="Yes")*Settings!$B$26+(D5="Unusable")*Settings!$B$27+(D5="Damaged")*Settings!$B$28+(H5>=Settings!$B$30)*Settings!$B$29) -> 3 | X5: =IF($A5="","",IF(W5>=Settings!$B$31,"High",IF(W5>=Settings!$B$32,"Medium","Low"))) -> Medium | Y5: =IF($A5="","",IF(V5>Settings!$B$21,"Yes","")) -> Yes | Z5: =IF($A5="","",COUNTIFS(Referrals!$B$5:$B$52,$A5,Referrals!$G$5:$G$52,"Referred")+COUNTIFS(Referrals!$B$5:$B$52,$A5,Referrals!$G$5:$G$52,"Acknowledged")) -> 0 | AA5: =IF($A5="","",COUNTIFS(Referrals!$B$5:$B$52,$A5,Referrals!$K$5:$K$52,"Overdue")) -> 0 | AB5: =IF($A5="","",IF(AND(J5>0,U5="Yes"),IF(COUNTIFS(Referrals!$B$5:$B$52,$A5,Referrals!$D$5:$D$52,"Nutrition / IYCF")=0,"Referral needed","Referred"),"")) -> Referred | AC5: =IF($A5="","",IF(N(Needs_Gaps!O5)>0,"Yes","")) | AD5: =IF($A5="","",IF(COUNTIFS(Maintenance_Log!$C$5:$C$40,$A5,Maintenance_Log!$H$5:$H$40,"<>Resolved")>0,"Yes","")) | AE5: =IF($A5="","",(Y5="Yes")+(AA5>0)+(AB5="Referral needed")+(AC5="Yes")+(AD5="Yes")) -> 1 | AF5: =IF($A5="",0,IF(AE5>0,AE5*100000+W5*1000+(1000-(ROW()-4)),0)) -> 103999 | AG5: =IFERROR(MATCH(ROW()-4,Import_Index!$H$5:$H$304,0),"") -> 42
A6: =IF($AG6="","",IFERROR(INDEX(Kobo_Import!$A$2:$CZ$301,$AG6,Field_Map!$B$13)&"","")) -> HH-002 | B6: =IF($AG6="","",IF(IFERROR(INDEX(Kobo_Import!$A$2:$CZ$301,$AG6,Field_Map!$B$9)&"","")="","",IFERROR(INDEX(Lists!$N$5:$N$19,MATCH(INDEX(Kobo_Import!$A$2:$CZ$301,$AG6,Field_Map!$B$9)&"",Lists!$M$5:$M$19,0)),INDEX(Kobo_Import!$A$2:$CZ$301,$AG6,Field_Map!$B$9)&""))) -> Site A – School Shelter | C6: =IF($AG6="","",IF(IFERROR(INDEX(Kobo_Import!$A$2:$CZ$301,$AG6,Field_Map!$B$14)&"","")="","",IFERROR(INDEX(Lists!$N$5:$N$19,MATCH(INDEX(Kobo_Import!$A$2:$CZ$301,$AG6,Field_Map!$B$14)&"",Lists!$M$5:$M$19,0)),INDEX(Kobo_Import!$A$2:$CZ$301,$AG6,Field_Map!$B$14)&""))) -> Classroom | D6: =IF($AG6="","",IF(IFERROR(INDEX(Kobo_Import!$A$2:$CZ$301,$AG6,Field_Map!$B$15)&"","")="","",IFERROR(INDEX(Lists!$N$5:$N$19,MATCH(INDEX(Kobo_Import!$A$2:$CZ$301,$AG6,Field_Map!$B$15)&"",Lists!$M$5:$M$19,0)),INDEX(Kobo_Import!$A$2:$CZ$301,$AG6,Field_Map!$B$15)&""))) -> Adequate | E6: =IF($A6="","",IFERROR(INDEX(Import_Index!$D$5:$D$304,MATCH($A6&"|registration",Import_Index!$I$5:$I$304,0)),F6)) -> 46049 | F6: =IF($AG6="","",INDEX(Import_Index!$D$5:$D$304,$AG6)) -> 46049 | G6: =IF($A6="","",COUNTIFS(Import_Index!$B$5:$B$304,$A6,Import_Index!$C$5:$C$304,"yes")) -> 1 | H6: =IF($AG6="","",IFERROR(VALUE(INDEX(Kobo_Import!$A$2:$CZ$301,$AG6,Field_Map!$B$16)&""),0)) -> 3 | I6: =IF($AG6="","",IF(IFERROR(INDEX(Kobo_Import!$A$2:$CZ$301,$AG6,Field_Map!$B$17)&"","")="","",IFERROR(INDEX(Lists!$N$5:$N$19,MATCH(INDEX(Kobo_Import!$A$2:$CZ$301,$AG6,Field_Map!$B$17)&"",Lists!$M$5:$M$19,0)),INDEX(Kobo_Import!$A$2:$CZ$301,$AG6,Field_Map!$B$17)&""))) -> Yes | J6: =IF($AG6="","",IFERROR(VALUE(INDEX(Kobo_Import!$A$2:$CZ$301,$AG6,Field_Map!$B$18)&""),0)) -> 0 | K6: =IF($AG6="","",IFERROR(VALUE(INDEX(Kobo_Import!$A$2:$CZ$301,$AG6,Field_Map!$B$19)&""),0)) -> 1 | L6: =IF($AG6="","",IFERROR(VALUE(INDEX(Kobo_Import!$A$2:$CZ$301,$AG6,Field_Map!$B$20)&""),0)) -> 2 | M6: =IF($AG6="","",IFERROR(VALUE(INDEX(Kobo_Import!$A$2:$CZ$301,$AG6,Field_Map!$B$21)&""),0)) -> 0 | N6: =IF($AG6="","",IFERROR(VALUE(INDEX(Kobo_Import!$A$2:$CZ$301,$AG6,Field_Map!$B$22)&""),0)) -> 2 | O6: =IF($AG6="","",IFERROR(VALUE(INDEX(Kobo_Import!$A$2:$CZ$301,$AG6,Field_Map!$B$23)&""),0)) -> 0 | P6: =IF($AG6="","",IFERROR(VALUE(INDEX(Kobo_Import!$A$2:$CZ$301,$AG6,Field_Map!$B$24)&""),0)) -> 0 | Q6: =IF($AG6="","",IFERROR(VALUE(INDEX(Kobo_Import!$A$2:$CZ$301,$AG6,Field_Map!$B$25)&""),0)) -> 5 | R6: =IF($AG6="","",IFERROR(VALUE(INDEX(Kobo_Import!$A$2:$CZ$301,$AG6,Field_Map!$B$26)&""),0)) -> 3 | S6: =IF($AG6="","",IFERROR(VALUE(INDEX(Kobo_Import!$A$2:$CZ$301,$AG6,Field_Map!$B$27)&""),0)) -> 0 | T6: =IF($AG6="","",IFERROR(VALUE(INDEX(Kobo_Import!$A$2:$CZ$301,$AG6,Field_Map!$B$28)&""),0)) -> 1 | U6: =IF($AG6="","",IF(IFERROR(INDEX(Kobo_Import!$A$2:$CZ$301,$AG6,Field_Map!$B$29)&"","")="","",IFERROR(INDEX(Lists!$N$5:$N$19,MATCH(INDEX(Kobo_Import!$A$2:$CZ$301,$AG6,Field_Map!$B$29)&"",Lists!$M$5:$M$19,0)),INDEX(Kobo_Import!$A$2:$CZ$301,$AG6,Field_Map!$B$29)&""))) | V6: =IF($A6="","",Settings!$B$5-F6) -> 4 | W6: =IF($A6="","",(J6>0)*Settings!$B$22+(P6>0)*Settings!$B$23+(M6>0)*Settings!$B$24+(O6>0)*Settings!$B$25+(I6="Yes")*Settings!$B$26+(D6="Unusable")*Settings!$B$27+(D6="Damaged")*Settings!$B$28+(H6>=Settings!$B$30)*Settings!$B$29) -> 1 | X6: =IF($A6="","",IF(W6>=Settings!$B$31,"High",IF(W6>=Settings!$B$32,"Medium","Low"))) -> Low | Y6: =IF($A6="","",IF(V6>Settings!$B$21,"Yes","")) | Z6: =IF($A6="","",COUNTIFS(Referrals!$B$5:$B$52,$A6,Referrals!$G$5:$G$52,"Referred")+COUNTIFS(Referrals!$B$5:$B$52,$A6,Referrals!$G$5:$G$52,"Acknowledged")) -> 0 | AA6: =IF($A6="","",COUNTIFS(Referrals!$B$5:$B$52,$A6,Referrals!$K$5:$K$52,"Overdue")) -> 0 | AB6: =IF($A6="","",IF(AND(J6>0,U6="Yes"),IF(COUNTIFS(Referrals!$B$5:$B$52,$A6,Referrals!$D$5:$D$52,"Nutrition / IYCF")=0,"Referral needed","Referred"),"")) | AC6: =IF($A6="","",IF(N(Needs_Gaps!O6)>0,"Yes","")) | AD6: =IF($A6="","",IF(COUNTIFS(Maintenance_Log!$C$5:$C$40,$A6,Maintenance_Log!$H$5:$H$40,"<>Resolved")>0,"Yes","")) | AE6: =IF($A6="","",(Y6="Yes")+(AA6>0)+(AB6="Referral needed")+(AC6="Yes")+(AD6="Yes")) -> 0 | AF6: =IF($A6="",0,IF(AE6>0,AE6*100000+W6*1000+(1000-(ROW()-4)),0)) -> 0 | AG6: =IFERROR(MATCH(ROW()-4,Import_Index!$H$5:$H$304,0),"") -> 141
A7: =IF($AG7="","",IFERROR(INDEX(Kobo_Import!$A$2:$CZ$301,$AG7,Field_Map!$B$13)&"","")) -> HH-003 | B7: =IF($AG7="","",IF(IFERROR(INDEX(Kobo_Import!$A$2:$CZ$301,$AG7,Field_Map!$B$9)&"","")="","",IFERROR(INDEX(Lists!$N$5:$N$19,MATCH(INDEX(Kobo_Import!$A$2:$CZ$301,$AG7,Field_Map!$B$9)&"",Lists!$M$5:$M$19,0)),INDEX(Kobo_Import!$A$2:$CZ$301,$AG7,Field_Map!$B$9)&""))) -> Site A – School Shelter | C7: =IF($AG7="","",IF(IFERROR(INDEX(Kobo_Import!$A$2:$CZ$301,$AG7,Field_Map!$B$14)&"","")="","",IFERROR(INDEX(Lists!$N$5:$N$19,MATCH(INDEX(Kobo_Import!$A$2:$CZ$301,$AG7,Field_Map!$B$14)&"",Lists!$M$5:$M$19,0)),INDEX(Kobo_Import!$A$2:$CZ$301,$AG7,Field_Map!$B$14)&""))) -> Classroom | D7: =IF($AG7="","",IF(IFERROR(INDEX(Kobo_Import!$A$2:$CZ$301,$AG7,Field_Map!$B$15)&"","")="","",IFERROR(INDEX(Lists!$N$5:$N$19,MATCH(INDEX(Kobo_Import!$A$2:$CZ$301,$AG7,Field_Map!$B$15)&"",Lists!$M$5:$M$19,0)),INDEX(Kobo_Import!$A$2:$CZ$301,$AG7,Field_Map!$B$15)&""))) -> Adequate | E7: =IF($A7="","",IFERROR(INDEX(Import_Index!$D$5:$D$304,MATCH($A7&"|registration",Import_Index!$I$5:$I$304,0)),F7)) -> 46030 | F7: =IF($AG7="","",INDEX(Import_Index!$D$5:$D$304,$AG7)) -> 46030 | G7: =IF($A7="","",COUNTIFS(Import_Index!$B$5:$B$304,$A7,Import_Index!$C$5:$C$304,"yes")) -> 1 | H7: =IF($AG7="","",IFERROR(VALUE(INDEX(Kobo_Import!$A$2:$CZ$301,$AG7,Field_Map!$B$16)&""),0)) -> 8 | I7: =IF($AG7="","",IF(IFERROR(INDEX(Kobo_Import!$A$2:$CZ$301,$AG7,Field_Map!$B$17)&"","")="","",IFERROR(INDEX(Lists!$N$5:$N$19,MATCH(INDEX(Kobo_Import!$A$2:$CZ$301,$AG7,Field_Map!$B$17)&"",Lists!$M$5:$M$19,0)),INDEX(Kobo_Import!$A$2:$CZ$301,$AG7,Field_Map!$B$17)&""))) -> No | J7: =IF($AG7="","",IFERROR(VALUE(INDEX(Kobo_Import!$A$2:$CZ$301,$AG7,Field_Map!$B$18)&""),0)) -> 0 | K7: =IF($AG7="","",IFERROR(VALUE(INDEX(Kobo_Import!$A$2:$CZ$301,$AG7,Field_Map!$B$19)&""),0)) -> 6 | L7: =IF($AG7="","",IFERROR(VALUE(INDEX(Kobo_Import!$A$2:$CZ$301,$AG7,Field_Map!$B$20)&""),0)) -> 2 | M7: =IF($AG7="","",IFERROR(VALUE(INDEX(Kobo_Import!$A$2:$CZ$301,$AG7,Field_Map!$B$21)&""),0)) -> 0 | N7: =IF($AG7="","",IFERROR(VALUE(INDEX(Kobo_Import!$A$2:$CZ$301,$AG7,Field_Map!$B$22)&""),0)) -> 1 | O7: =IF($AG7="","",IFERROR(VALUE(INDEX(Kobo_Import!$A$2:$CZ$301,$AG7,Field_Map!$B$23)&""),0)) -> 0 | P7: =IF($AG7="","",IFERROR(VALUE(INDEX(Kobo_Import!$A$2:$CZ$301,$AG7,Field_Map!$B$24)&""),0)) -> 0 | Q7: =IF($AG7="","",IFERROR(VALUE(INDEX(Kobo_Import!$A$2:$CZ$301,$AG7,Field_Map!$B$25)&""),0)) -> 9 | R7: =IF($AG7="","",IFERROR(VALUE(INDEX(Kobo_Import!$A$2:$CZ$301,$AG7,Field_Map!$B$26)&""),0)) -> 2 | S7: =IF($AG7="","",IFERROR(VALUE(INDEX(Kobo_Import!$A$2:$CZ$301,$AG7,Field_Map!$B$27)&""),0)) -> 1 | T7: =IF($AG7="","",IFERROR(VALUE(INDEX(Kobo_Import!$A$2:$CZ$301,$AG7,Field_Map!$B$28)&""),0)) -> 0 | U7: =IF($AG7="","",IF(IFERROR(INDEX(Kobo_Import!$A$2:$CZ$301,$AG7,Field_Map!$B$29)&"","")="","",IFERROR(INDEX(Lists!$N$5:$N$19,MATCH(INDEX(Kobo_Import!$A$2:$CZ$301,$AG7,Field_Map!$B$29)&"",Lists!$M$5:$M$19,0)),INDEX(Kobo_Import!$A$2:$CZ$301,$AG7,Field_Map!$B$29)&""))) | V7: =IF($A7="","",Settings!$B$5-F7) -> 23 | W7: =IF($A7="","",(J7>0)*Settings!$B$22+(P7>0)*Settings!$B$23+(M7>0)*Settings!$B$24+(O7>0)*Settings!$B$25+(I7="Yes")*Settings!$B$26+(D7="Unusable")*Settings!$B$27+(D7="Damaged")*Settings!$B$28+(H7>=Settings!$B$30)*Settings!$B$29) -> 0 | X7: =IF($A7="","",IF(W7>=Settings!$B$31,"High",IF(W7>=Settings!$B$32,"Medium","Low"))) -> Low | Y7: =IF($A7="","",IF(V7>Settings!$B$21,"Yes","")) | Z7: =IF($A7="","",COUNTIFS(Referrals!$B$5:$B$52,$A7,Referrals!$G$5:$G$52,"Referred")+COUNTIFS(Referrals!$B$5:$B$52,$A7,Referrals!$G$5:$G$52,"Acknowledged")) -> 0 | AA7: =IF($A7="","",COUNTIFS(Referrals!$B$5:$B$52,$A7,Referrals!$K$5:$K$52,"Overdue")) -> 0 | AB7: =IF($A7="","",IF(AND(J7>0,U7="Yes"),IF(COUNTIFS(Referrals!$B$5:$B$52,$A7,Referrals!$D$5:$D$52,"Nutrition / IYCF")=0,"Referral needed","Referred"),"")) | AC7: =IF($A7="","",IF(N(Needs_Gaps!O7)>0,"Yes","")) | AD7: =IF($A7="","",IF(COUNTIFS(Maintenance_Log!$C$5:$C$40,$A7,Maintenance_Log!$H$5:$H$40,"<>Resolved")>0,"Yes","")) | AE7: =IF($A7="","",(Y7="Yes")+(AA7>0)+(AB7="Referral needed")+(AC7="Yes")+(AD7="Yes")) -> 0 | AF7: =IF($A7="",0,IF(AE7>0,AE7*100000+W7*1000+(1000-(ROW()-4)),0)) -> 0 | AG7: =IFERROR(MATCH(ROW()-4,Import_Index!$H$5:$H$304,0),"") -> 58
A8: =IF($AG8="","",IFERROR(INDEX(Kobo_Import!$A$2:$CZ$301,$AG8,Field_Map!$B$13)&"","")) -> HH-004 | B8: =IF($AG8="","",IF(IFERROR(INDEX(Kobo_Import!$A$2:$CZ$301,$AG8,Field_Map!$B$9)&"","")="","",IFERROR(INDEX(Lists!$N$5:$N$19,MATCH(INDEX(Kobo_Import!$A$2:$CZ$301,$AG8,Field_Map!$B$9)&"",Lists!$M$5:$M$19,0)),INDEX(Kobo_Import!$A$2:$CZ$301,$AG8,Field_Map!$B$9)&""))) -> Site A – School Shelter | C8: =IF($AG8="","",IF(IFERROR(INDEX(Kobo_Import!$A$2:$CZ$301,$AG8,Field_Map!$B$14)&"","")="","",IFERROR(INDEX(Lists!$N$5:$N$19,MATCH(INDEX(Kobo_Import!$A$2:$CZ$301,$AG8,Field_Map!$B$14)&"",Lists!$M$5:$M$19,0)),INDEX(Kobo_Import!$A$2:$CZ$301,$AG8,Field_Map!$B$14)&""))) -> Classroom | D8: =IF($AG8="","",IF(IFERROR(INDEX(Kobo_Import!$A$2:$CZ$301,$AG8,Field_Map!$B$15)&"","")="","",IFERROR(INDEX(Lists!$N$5:$N$19,MATCH(INDEX(Kobo_Import!$A$2:$CZ$301,$AG8,Field_Map!$B$15)&"",Lists!$M$5:$M$19,0)),INDEX(Kobo_Import!$A$2:$CZ$301,$AG8,Field_Map!$B$15)&""))) -> Adequate | E8: =IF($A8="","",IFERROR(INDEX(Import_Index!$D$5:$D$304,MATCH($A8&"|registration",Import_Index!$I$5:$I$304,0)),F8)) -> 46021 | F8: =IF($AG8="","",INDEX(Import_Index!$D$5:$D$304,$AG8)) -> 46034 | G8: =IF($A8="","",COUNTIFS(Import_Index!$B$5:$B$304,$A8,Import_Index!$C$5:$C$304,"yes")) -> 2 | H8: =IF($AG8="","",IFERROR(VALUE(INDEX(Kobo_Import!$A$2:$CZ$301,$AG8,Field_Map!$B$16)&""),0)) -> 7 | I8: =IF($AG8="","",IF(IFERROR(INDEX(Kobo_Import!$A$2:$CZ$301,$AG8,Field_Map!$B$17)&"","")="","",IFERROR(INDEX(Lists!$N$5:$N$19,MATCH(INDEX(Kobo_Import!$A$2:$CZ$301,$AG8,Field_Map!$B$17)&"",Lists!$M$5:$M$19,0)),INDEX(Kobo_Import!$A$2:$CZ$301,$AG8,Field_Map!$B$17)&""))) -> No | J8: =IF($AG8="","",IFERROR(VALUE(INDEX(Kobo_Import!$A$2:$CZ$301,$AG8,Field_Map!$B$18)&""),0)) -> 2 | K8: =IF($AG8="","",IFERROR(VALUE(INDEX(Kobo_Import!$A$2:$CZ$301,$AG8,Field_Map!$B$19)&""),0)) -> 3 | L8: =IF($AG8="","",IFERROR(VALUE(INDEX(Kobo_Import!$A$2:$CZ$301,$AG8,Field_Map!$B$20)&""),0)) -> 1 | M8: =IF($AG8="","",IFERROR(VALUE(INDEX(Kobo_Import!$A$2:$CZ$301,$AG8,Field_Map!$B$21)&""),0)) -> 1 | N8: =IF($AG8="","",IFERROR(VALUE(INDEX(Kobo_Import!$A$2:$CZ$301,$AG8,Field_Map!$B$22)&""),0)) -> 1 | O8: =IF($AG8="","",IFERROR(VALUE(INDEX(Kobo_Import!$A$2:$CZ$301,$AG8,Field_Map!$B$23)&""),0)) -> 1 | P8: =IF($AG8="","",IFERROR(VALUE(INDEX(Kobo_Import!$A$2:$CZ$301,$AG8,Field_Map!$B$24)&""),0)) -> 0 | Q8: =IF($AG8="","",IFERROR(VALUE(INDEX(Kobo_Import!$A$2:$CZ$301,$AG8,Field_Map!$B$25)&""),0)) -> 2 | R8: =IF($AG8="","",IFERROR(VALUE(INDEX(Kobo_Import!$A$2:$CZ$301,$AG8,Field_Map!$B$26)&""),0)) -> 3 | S8: =IF($AG8="","",IFERROR(VALUE(INDEX(Kobo_Import!$A$2:$CZ$301,$AG8,Field_Map!$B$27)&""),0)) -> 5 | T8: =IF($AG8="","",IFERROR(VALUE(INDEX(Kobo_Import!$A$2:$CZ$301,$AG8,Field_Map!$B$28)&""),0)) -> 0 | U8: =IF($AG8="","",IF(IFERROR(INDEX(Kobo_Import!$A$2:$CZ$301,$AG8,Field_Map!$B$29)&"","")="","",IFERROR(INDEX(Lists!$N$5:$N$19,MATCH(INDEX(Kobo_Import!$A$2:$CZ$301,$AG8,Field_Map!$B$29)&"",Lists!$M$5:$M$19,0)),INDEX(Kobo_Import!$A$2:$CZ$301,$AG8,Field_Map!$B$29)&""))) -> No | V8: =IF($A8="","",Settings!$B$5-F8) -> 19 | W8: =IF($A8="","",(J8>0)*Settings!$B$22+(P8>0)*Settings!$B$23+(M8>0)*Settings!$B$24+(O8>0)*Settings!$B$25+(I8="Yes")*Settings!$B$26+(D8="Unusable")*Settings!$B$27+(D8="Damaged")*Settings!$B$28+(H8>=Settings!$B$30)*Settings!$B$29) -> 4 | X8: =IF($A8="","",IF(W8>=Settings!$B$31,"High",IF(W8>=Settings!$B$32,"Medium","Low"))) -> Medium | Y8: =IF($A8="","",IF(V8>Settings!$B$21,"Yes","")) | Z8: =IF($A8="","",COUNTIFS(Referrals!$B$5:$B$52,$A8,Referrals!$G$5:$G$52,"Referred")+COUNTIFS(Referrals!$B$5:$B$52,$A8,Referrals!$G$5:$G$52,"Acknowledged")) -> 0 | AA8: =IF($A8="","",COUNTIFS(Referrals!$B$5:$B$52,$A8,Referrals!$K$5:$K$52,"Overdue")) -> 0 | AB8: =IF($A8="","",IF(AND(J8>0,U8="Yes"),IF(COUNTIFS(Referrals!$B$5:$B$52,$A8,Referrals!$D$5:$D$52,"Nutrition / IYCF")=0,"Referral needed","Referred"),"")) | AC8: =IF($A8="","",IF(N(Needs_Gaps!O8)>0,"Yes","")) | AD8: =IF($A8="","",IF(COUNTIFS(Maintenance_Log!$C$5:$C$40,$A8,Maintenance_Log!$H$5:$H$40,"<>Resolved")>0,"Yes","")) | AE8: =IF($A8="","",(Y8="Yes")+(AA8>0)+(AB8="Referral needed")+(AC8="Yes")+(AD8="Yes")) -> 0 | AF8: =IF($A8="",0,IF(AE8>0,AE8*100000+W8*1000+(1000-(ROW()-4)),0)) -> 0 | AG8: =IFERROR(MATCH(ROW()-4,Import_Index!$H$5:$H$304,0),"") -> 76
A9: =IF($AG9="","",IFERROR(INDEX(Kobo_Import!$A$2:$CZ$301,$AG9,Field_Map!$B$13)&"","")) -> HH-005 | B9: =IF($AG9="","",IF(IFERROR(INDEX(Kobo_Import!$A$2:$CZ$301,$AG9,Field_Map!$B$9)&"","")="","",IFERROR(INDEX(Lists!$N$5:$N$19,MATCH(INDEX(Kobo_Import!$A$2:$CZ$301,$AG9,Field_Map!$B$9)&"",Lists!$M$5:$M$19,0)),INDEX(Kobo_Import!$A$2:$CZ$301,$AG9,Field_Map!$B$9)&""))) -> Site A – School Shelter | C9: =IF($AG9="","",IF(IFERROR(INDEX(Kobo_Import!$A$2:$CZ$301,$AG9,Field_Map!$B$14)&"","")="","",IFERROR(INDEX(Lists!$N$5:$N$19,MATCH(INDEX(Kobo_Import!$A$2:$CZ$301,$AG9,Field_Map!$B$14)&"",Lists!$M$5:$M$19,0)),INDEX(Kobo_Import!$A$2:$CZ$301,$AG9,Field_Map!$B$14)&""))) -> Classroom | D9: =IF($AG9="","",IF(IFERROR(INDEX(Kobo_Import!$A$2:$CZ$301,$AG9,Field_Map!$B$15)&"","")="","",IFERROR(INDEX(Lists!$N$5:$N$19,MATCH(INDEX(Kobo_Import!$A$2:$CZ$301,$AG9,Field_Map!$B$15)&"",Lists!$M$5:$M$19,0)),INDEX(Kobo_Import!$A$2:$CZ$301,$AG9,Field_Map!$B$15)&""))) -> Adequate | E9: =IF($A9="","",IFERROR(INDEX(Import_Index!$D$5:$D$304,MATCH($A9&"|registration",Import_Index!$I$5:$I$304,0)),F9)) -> 46009 | F9: =IF($AG9="","",INDEX(Import_Index!$D$5:$D$304,$AG9)) -> 46045 | G9: =IF($A9="","",COUNTIFS(Import_Index!$B$5:$B$304,$A9,Import_Index!$C$5:$C$304,"yes")) -> 2 | H9: =IF($AG9="","",IFERROR(VALUE(INDEX(Kobo_Import!$A$2:$CZ$301,$AG9,Field_Map!$B$16)&""),0)) -> 7 | I9: =IF($AG9="","",IF(IFERROR(INDEX(Kobo_Import!$A$2:$CZ$301,$AG9,Field_Map!$B$17)&"","")="","",IFERROR(INDEX(Lists!$N$5:$N$19,MATCH(INDEX(Kobo_Import!$A$2:$CZ$301,$AG9,Field_Map!$B$17)&"",Lists!$M$5:$M$19,0)),INDEX(Kobo_Import!$A$2:$CZ$301,$AG9,Field_Map!$B$17)&""))) -> No | J9: =IF($AG9="","",IFERROR(VALUE(INDEX(Kobo_Import!$A$2:$CZ$301,$AG9,Field_Map!$B$18)&""),0)) -> 1 | K9: =IF($AG9="","",IFERROR(VALUE(INDEX(Kobo_Import!$A$2:$CZ$301,$AG9,Field_Map!$B$19)&""),0)) -> 4 | L9: =IF($AG9="","",IFERROR(VALUE(INDEX(Kobo_Import!$A$2:$CZ$301,$AG9,Field_Map!$B$20)&""),0)) -> 2 | M9: =IF($AG9="","",IFERROR(VALUE(INDEX(Kobo_Import!$A$2:$CZ$301,$AG9,Field_Map!$B$21)&""),0)) -> 0 | N9: =IF($AG9="","",IFERROR(VALUE(INDEX(Kobo_Import!$A$2:$CZ$301,$AG9,Field_Map!$B$22)&""),0)) -> 1 | O9: =IF($AG9="","",IFERROR(VALUE(INDEX(Kobo_Import!$A$2:$CZ$301,$AG9,Field_Map!$B$23)&""),0)) -> 1 | P9: =IF($AG9="","",IFERROR(VALUE(INDEX(Kobo_Import!$A$2:$CZ$301,$AG9,Field_Map!$B$24)&""),0)) -> 0 | Q9: =IF($AG9="","",IFERROR(VALUE(INDEX(Kobo_Import!$A$2:$CZ$301,$AG9,Field_Map!$B$25)&""),0)) -> 8 | R9: =IF($AG9="","",IFERROR(VALUE(INDEX(Kobo_Import!$A$2:$CZ$301,$AG9,Field_Map!$B$26)&""),0)) -> 4 | S9: =IF($AG9="","",IFERROR(VALUE(INDEX(Kobo_Import!$A$2:$CZ$301,$AG9,Field_Map!$B$27)&""),0)) -> 3 | T9: =IF($AG9="","",IFERROR(VALUE(INDEX(Kobo_Import!$A$2:$CZ$301,$AG9,Field_Map!$B$28)&""),0)) -> 0 | U9: =IF($AG9="","",IF(IFERROR(INDEX(Kobo_Import!$A$2:$CZ$301,$AG9,Field_Map!$B$29)&"","")="","",IFERROR(INDEX(Lists!$N$5:$N$19,MATCH(INDEX(Kobo_Import!$A$2:$CZ$301,$AG9,Field_Map!$B$29)&"",Lists!$M$5:$M$19,0)),INDEX(Kobo_Import!$A$2:$CZ$301,$AG9,Field_Map!$B$29)&""))) -> No | V9: =IF($A9="","",Settings!$B$5-F9) -> 8 | W9: =IF($A9="","",(J9>0)*Settings!$B$22+(P9>0)*Settings!$B$23+(M9>0)*Settings!$B$24+(O9>0)*Settings!$B$25+(I9="Yes")*Settings!$B$26+(D9="Unusable")*Settings!$B$27+(D9="Damaged")*Settings!$B$28+(H9>=Settings!$B$30)*Settings!$B$29) -> 3 | X9: =IF($A9="","",IF(W9>=Settings!$B$31,"High",IF(W9>=Settings!$B$32,"Medium","Low"))) -> Medium | Y9: =IF($A9="","",IF(V9>Settings!$B$21,"Yes","")) | Z9: =IF($A9="","",COUNTIFS(Referrals!$B$5:$B$52,$A9,Referrals!$G$5:$G$52,"Referred")+COUNTIFS(Referrals!$B$5:$B$52,$A9,Referrals!$G$5:$G$52,"Acknowledged")) -> 0 | AA9: =IF($A9="","",COUNTIFS(Referrals!$B$5:$B$52,$A9,Referrals!$K$5:$K$52,"Overdue")) -> 0 | AB9: =IF($A9="","",IF(AND(J9>0,U9="Yes"),IF(COUNTIFS(Referrals!$B$5:$B$52,$A9,Referrals!$D$5:$D$52,"Nutrition / IYCF")=0,"Referral needed","Referred"),"")) | AC9: =IF($A9="","",IF(N(Needs_Gaps!O9)>0,"Yes","")) | AD9: =IF($A9="","",IF(COUNTIFS(Maintenance_Log!$C$5:$C$40,$A9,Maintenance_Log!$H$5:$H$40,"<>Resolved")>0,"Yes","")) | AE9: =IF($A9="","",(Y9="Yes")+(AA9>0)+(AB9="Referral needed")+(AC9="Yes")+(AD9="Yes")) -> 0 | AF9: =IF($A9="",0,IF(AE9>0,AE9*100000+W9*1000+(1000-(ROW()-4)),0)) -> 0 | AG9: =IFERROR(MATCH(ROW()-4,Import_Index!$H$5:$H$304,0),"") -> 124
A10: =IF($AG10="","",IFERROR(INDEX(Kobo_Import!$A$2:$CZ$301,$AG10,Field_Map!$B$13)&"","")) -> HH-006 | B10: =IF($AG10="","",IF(IFERROR(INDEX(Kobo_Import!$A$2:$CZ$301,$AG10,Field_Map!$B$9)&"","")="","",IFERROR(INDEX(Lists!$N$5:$N$19,MATCH(INDEX(Kobo_Import!$A$2:$CZ$301,$AG10,Field_Map!$B$9)&"",Lists!$M$5:$M$19,0)),INDEX(Kobo_Import!$A$2:$CZ$301,$AG10,Field_Map!$B$9)&""))) -> Site A – School Shelter | C10: =IF($AG10="","",IF(IFERROR(INDEX(Kobo_Import!$A$2:$CZ$301,$AG10,Field_Map!$B$14)&"","")="","",IFERROR(INDEX(Lists!$N$5:$N$19,MATCH(INDEX(Kobo_Import!$A$2:$CZ$301,$AG10,Field_Map!$B$14)&"",Lists!$M$5:$M$19,0)),INDEX(Kobo_Import!$A$2:$CZ$301,$AG10,Field_Map!$B$14)&""))) -> Classroom | D10: =IF($AG10="","",IF(IFERROR(INDEX(Kobo_Import!$A$2:$CZ$301,$AG10,Field_Map!$B$15)&"","")="","",IFERROR(INDEX(Lists!$N$5:$N$19,MATCH(INDEX(Kobo_Import!$A$2:$CZ$301,$AG10,Field_Map!$B$15)&"",Lists!$M$5:$M$19,0)),INDEX(Kobo_Import!$A$2:$CZ$301,$AG10,Field_Map!$B$15)&""))) -> Adequate | E10: =IF($A10="","",IFERROR(INDEX(Import_Index!$D$5:$D$304,MATCH($A10&"|registration",Import_Index!$I$5:$I$304,0)),F10)) -> 46046 | F10: =IF($AG10="","",INDEX(Import_Index!$D$5:$D$304,$AG10)) -> 46046 | G10: =IF($A10="","",COUNTIFS(Import_Index!$B$5:$B$304,$A10,Import_Index!$C$5:$C$304,"yes")) -> 1 | H10: =IF($AG10="","",IFERROR(VALUE(INDEX(Kobo_Import!$A$2:$CZ$301,$AG10,Field_Map!$B$16)&""),0)) -> 11 | I10: =IF($AG10="","",IF(IFERROR(INDEX(Kobo_Import!$A$2:$CZ$301,$AG10,Field_Map!$B$17)&"","")="","",IFERROR(INDEX(Lists!$N$5:$N$19,MATCH(INDEX(Kobo_Import!$A$2:$CZ$301,$AG10,Field_Map!$B$17)&"",Lists!$M$5:$M$19,0)),INDEX(Kobo_Import!$A$2:$CZ$301,$AG10,Field_Map!$B$17)&""))) -> No | J10: =IF($AG10="","",IFERROR(VALUE(INDEX(Kobo_Import!$A$2:$CZ$301,$AG10,Field_Map!$B$18)&""),0)) -> 1 | K10: =IF($AG10="","",IFERROR(VALUE(INDEX(Kobo_Import!$A$2:$CZ$301,$AG10,Field_Map!$B$19)&""),0)) -> 8 | L10: =IF($AG10="","",IFERROR(VALUE(INDEX(Kobo_Import!$A$2:$CZ$301,$AG10,Field_Map!$B$20)&""),0)) -> 2 | M10: =IF($AG10="","",IFERROR(VALUE(INDEX(Kobo_Import!$A$2:$CZ$301,$AG10,Field_Map!$B$21)&""),0)) -> 0 | N10: =IF($AG10="","",IFERROR(VALUE(INDEX(Kobo_Import!$A$2:$CZ$301,$AG10,Field_Map!$B$22)&""),0)) -> 2 | O10: =IF($AG10="","",IFERROR(VALUE(INDEX(Kobo_Import!$A$2:$CZ$301,$AG10,Field_Map!$B$23)&""),0)) -> 1 | P10: =IF($AG10="","",IFERROR(VALUE(INDEX(Kobo_Import!$A$2:$CZ$301,$AG10,Field_Map!$B$24)&""),0)) -> 2 | Q10: =IF($AG10="","",IFERROR(VALUE(INDEX(Kobo_Import!$A$2:$CZ$301,$AG10,Field_Map!$B$25)&""),0)) -> 11 | R10: =IF($AG10="","",IFERROR(VALUE(INDEX(Kobo_Import!$A$2:$CZ$301,$AG10,Field_Map!$B$26)&""),0)) -> 4 | S10: =IF($AG10="","",IFERROR(VALUE(INDEX(Kobo_Import!$A$2:$CZ$301,$AG10,Field_Map!$B$27)&""),0)) -> 6 | T10: =IF($AG10="","",IFERROR(VALUE(INDEX(Kobo_Import!$A$2:$CZ$301,$AG10,Field_Map!$B$28)&""),0)) -> 2 | U10: =IF($AG10="","",IF(IFERROR(INDEX(Kobo_Import!$A$2:$CZ$301,$AG10,Field_Map!$B$29)&"","")="","",IFERROR(INDEX(Lists!$N$5:$N$19,MATCH(INDEX(Kobo_Import!$A$2:$CZ$301,$AG10,Field_Map!$B$29)&"",Lists!$M$5:$M$19,0)),INDEX(Kobo_Import!$A$2:$CZ$301,$AG10,Field_Map!$B$29)&""))) -> No | V10: =IF($A10="","",Settings!$B$5-F10) -> 7 | W10: =IF($A10="","",(J10>0)*Settings!$B$22+(P10>0)*Settings!$B$23+(M10>0)*Settings!$B$24+(O10>0)*Settings!$B$25+(I10="Yes")*Settings!$B$26+(D10="Unusable")*Settings!$B$27+(D10="Damaged")*Settings!$B$28+(H10>=Settings!$B$30)*Settings!$B$29) -> 6 | X10: =IF($A10="","",IF(W10>=Settings!$B$31,"High",IF(W10>=Settings!$B$32,"Medium","Low"))) -> High | Y10: =IF($A10="","",IF(V10>Settings!$B$21,"Yes","")) | Z10: =IF($A10="","",COUNTIFS(Referrals!$B$5:$B$52,$A10,Referrals!$G$5:$G$52,"Referred")+COUNTIFS(Referrals!$B$5:$B$52,$A10,Referrals!$G$5:$G$52,"Acknowledged")) -> 0 | AA10: =IF($A10="","",COUNTIFS(Referrals!$B$5:$B$52,$A10,Referrals!$K$5:$K$52,"Overdue")) -> 0 | AB10: =IF($A10="","",IF(AND(J10>0,U10="Yes"),IF(COUNTIFS(Referrals!$B$5:$B$52,$A10,Referrals!$D$5:$D$52,"Nutrition / IYCF")=0,"Referral needed","Referred"),"")) | AC10: =IF($A10="","",IF(N(Needs_Gaps!O10)>0,"Yes","")) | AD10: =IF($A10="","",IF(COUNTIFS(Maintenance_Log!$C$5:$C$40,$A10,Maintenance_Log!$H$5:$H$40,"<>Resolved")>0,"Yes","")) | AE10: =IF($A10="","",(Y10="Yes")+(AA10>0)+(AB10="Referral needed")+(AC10="Yes")+(AD10="Yes")) -> 0 | AF10: =IF($A10="",0,IF(AE10>0,AE10*100000+W10*1000+(1000-(ROW()-4)),0)) -> 0 | AG10: =IFERROR(MATCH(ROW()-4,Import_Index!$H$5:$H$304,0),"") -> 127
